#VRML_SIM R2025a utf8

EXTERNPROTO "https://raw.githubusercontent.com/cyberbotics/webots/R2023b/projects/objects/backgrounds/protos/TexturedBackground.proto"
EXTERNPROTO "https://raw.githubusercontent.com/cyberbotics/webots/R2023b/projects/objects/backgrounds/protos/TexturedBackgroundLight.proto"
EXTERNPROTO "https://raw.githubusercontent.com/cyberbotics/webots/R2023b/projects/objects/floors/protos/RectangleArena.proto"

WorldInfo {
}
Viewpoint {
  orientation 0.16996965006546044 -0.5071935636312381 -0.8449053243220035 5.527966630449281
  position -0.8061558476879567 -0.9843772729929651 0.39519885702753993
}
TexturedBackground {
}
TexturedBackgroundLight {
}
RectangleArena {
  floorSize 2 2
  floorAppearance PBRAppearance {
    roughness 1
    roughnessMap ImageTexture {
      url [
        "https://raw.githubusercontent.com/cyberbotics/webots/R2023b/projects/appearances/protos/textures/parquetry/mosaic_parquetry_roughness.jpg"
      ]
    }
    metalness 0
    normalMap ImageTexture {
      url [
        "https://raw.githubusercontent.com/cyberbotics/webots/R2023b/projects/appearances/protos/textures/parquetry/mosaic_parquetry_normal.jpg"
      ]
    }
    occlusionMap ImageTexture {
      url [
        "https://raw.githubusercontent.com/cyberbotics/webots/R2023b/projects/appearances/protos/textures/parquetry/mosaic_parquetry_occlusion.jpg"
      ]
    }
  }
}
Transform {
  scale 0.01 0.01 0.01
  children [
    DEF OuterPath Shape {
      appearance PBRAppearance {
        baseColor 0 0 0
        roughness 1
        metalness 0
      }
      geometry Mesh {
        url [
          "../path/outer_path.obj"
        ]
      }
    }
  ]
}
Transform {
  scale 0.01 0.01 0.01
  children [
    DEF InnerPath Shape {
      appearance PBRAppearance {
        baseColor 0 0 0
        roughness 1
        metalness 0
      }
      geometry Mesh {
        url [
          "../path/inner_path.obj"
        ]
      }
    }
  ]
}
Solid {
  translation 0.45 -0.73 0.05
  rotation 0 0 1 0.261799
  children [
    Shape {
      appearance PBRAppearance {
        baseColor 0 0 0
        roughness 1
        metalness 0
      }
      geometry Box {
        size 0.1 0.1 0.1
      }
    }
  ]
}
Solid {
  translation 0.666748 -0.198009 0.05
  rotation 0 0 -1 -1.308995307
  children [
    Shape {
      appearance PBRAppearance {
        baseColor 0 0 0
        roughness 1
        metalness 0
      }
      geometry Box {
        size 0.2 0.1 0.1
      }
    }
  ]
  name "solid(1)"
}
Solid {
  translation 0.36358 0.381911 0.05
  rotation 0 0 -1 -1.047195307
  children [
    Shape {
      appearance PBRAppearance {
        baseColor 0 0 0
        roughness 1
        metalness 0
      }
      geometry Box {
        size 0.12 0.1 0.1
      }
    }
  ]
  name "solid(3)"
}
Solid {
  translation -0.380764 0.661551 0.05
  rotation 0 0 1 2.09439
  children [
    Shape {
      appearance PBRAppearance {
        baseColor 0 0 0
        roughness 1
        metalness 0
      }
      geometry Box {
        size 0.12 0.1 0.1
      }
    }
  ]
  name "solid(4)"
}
Solid {
  translation -0.545793 -0.075621 0.05
  rotation 0 0 1 1.83259
  children [
    Shape {
      appearance PBRAppearance {
        baseColor 0 0 0
        roughness 1
        metalness 0
      }
      geometry Box {
        size 0.1 0.3 0.1
      }
    }
  ]
  name "solid(5)"
}
Solid {
  translation -0.356546 -0.527723 0
  rotation 0 0 1 2.87979
  children [
    Shape {
      appearance PBRAppearance {
        baseColor 1 0 0
        roughness 1
        metalness 0
      }
      geometry Box {
        size 0.03 0.55 0.0005
      }
    }
  ]
  name "solid(6)"
}
Robot {
  translation -0.4380646254774929 -0.4818662586322746 -0.00408238080857229
  rotation -0.3779514332654951 0.6369078543206076 -0.671938315023989 0.03598712530574463
  children [
    DEF Body Pose {
      translation 0 0 0.032
      children [
        Shape {
          appearance PBRAppearance {
            baseColor 0 0 1
            roughness 1
            metalness 0
          }
          geometry Cylinder {
            height 0.05
            radius 0.0355
          }
        }
      ]
    }
    HingeJoint {
      jointParameters HingeJointParameters {
        position 249.74236446266994
        axis 0 1 0
        anchor 0 0.0355 0.0245
      }
      device [
        RotationalMotor {
          name "left wheel motor"
        }
        PositionSensor {
          name "left wheel sensor"
        }
      ]
      endPoint Solid {
        translation -0.0007010942741485477 0.03550374682921392 0.0247732587946212
        rotation -0.5720775657550264 0.5813194178091353 -0.5786147191679896 4.179908393520483
        children [
          DEF wheel Shape {
            appearance PBRAppearance {
              baseColor 1 0 0.4
              roughness 1
              metalness 0
            }
            geometry Cylinder {
              height 0.01
              radius 0.0205
            }
          }
        ]
        boundingObject USE wheel
        physics DEF wheel_physics Physics {
          centerOfMass [
            0 0 0
          ]
        }
      }
    }
    Camera {
      translation 0.0355 0 0.05
      children [
        Solid {
          translation -0.002 0 0
          rotation 0 1 0 1.57
          children [
            Shape {
              appearance PBRAppearance {
                baseColor 0.5 1 0
                roughness 1
                metalness 0
              }
              geometry Cylinder {
                height 0.01
                radius 0.006
              }
            }
          ]
        }
      ]
      fieldOfView 0.84
      width 104
      height 78
      lens Lens {
      }
      focus Focus {
      }
      recognition Recognition {
      }
    }
    HingeJoint {
      jointParameters HingeJointParameters {
        position 254.60272574623303
        axis 0 1 0
        anchor 0 -0.0355 0.0245
      }
      device [
        RotationalMotor {
          name "right wheel motor"
        }
        PositionSensor {
          name "right wheel sensor"
        }
      ]
      endPoint Solid {
        translation -0.0003214014376132672 -0.035496239108183114 0.02383357402867038
        rotation 0.04827126476419472 -0.7069985686832136 0.705565665886565 3.049028019720357
        children [
          DEF wheel Shape {
            appearance PBRAppearance {
              baseColor 1 0 0.4
              roughness 1
              metalness 0
            }
            geometry Cylinder {
              height 0.01
              radius 0.0205
            }
          }
        ]
        name "solid(1)"
        boundingObject USE wheel
        physics DEF wheel_physics Physics {
          centerOfMass [
            0 0 0
          ]
        }
      }
    }
  ]
  boundingObject USE Body
  physics Physics {
    centerOfMass [
      0 0 0
    ]
  }
  controller "controller_Base"
}
